Workbook

Sheet Overview
E9: Firebird
E11: Modules | F11: TC count | G11: Pass | H11: Fail | I11: N/A | J11: Blocker
E12: Practice Setup | F12: 69 | G12: =COUNTIF(PracticeManagement!F:F,"Pass") -> 0 | H12: =COUNTIF(PracticeManagement!F:F,"Fail") -> 0 | I12: =COUNTIF(PracticeManagement!F:F,"N/A") -> 0 | J12: =COUNTIF(PracticeManagement!F:F,"Blocker") -> 0
E13: Front Desk | F13: 135 | G13: =COUNTIF(FrontDesk!J:J,"Pass") -> 0 | H13: =COUNTIF(FrontDesk!J:J,"Fail") -> 0 | I13: =COUNTIF(FrontDesk!J:J,"N/A") -> 0 | J13: =COUNTIF(FrontDesk!J:J,"Blocker") -> 0
E14: Messaging | F14: 51 | G14: =COUNTIF(Message!J:J,"Pass") -> 0 | H14: =COUNTIF(Message!J:J,"Fail") -> 0 | I14: =COUNTIF(Message!J:J,"N/A") -> 0 | J14: =COUNTIF(Message!J:J,"Blocker") -> 0
E15: Nurse | F15: 133 | G15: =COUNTIF(Nurse!H:H,"Pass") -> 0 | H15: =COUNTIF(Nurse!H:H,"Fail") -> 0 | I15: =COUNTIF(Nurse!H:H,"N/A") -> 0 | J15: =COUNTIF(Nurse!H:H,"Blocker") -> 0
E16: Billing | F16: 243 | G16: =COUNTIF(Billing!I:I,"Pass") -> 0 | H16: =COUNTIF(Billing!I:I,"Fail") -> 0 | I16: =COUNTIF(Billing!I:I,"N/A") -> 0 | J16: =COUNTIF(Billing!I:I,"Blocker") -> 0
E17: Provider | F17: 127 | G17: =COUNTIF(#REF!,"Pass") -> 0 | H17: =COUNTIF(#REF!,"Fail") -> 0 | I17: =COUNTIF(#REF!,"N/A") -> 0 | J17: =COUNTIF(#REF!,"Blocker") -> 0
E18: New calendar | F18: 79 | G18: =COUNTIF(NewCalendar!F:F,"Pass") -> 0 | H18: =COUNTIF(NewCalendar!F:F,"Fail") -> 0 | I18: =COUNTIF(NewCalendar!F:F,"N/A") -> 0 | J18: =COUNTIF(NewCalendar!F:F,"Blocker") -> 0
E19: Total | F19: =SUM(F12:F18) -> 837
E23: MySQL
E25: Modules | F25: TC count | G25: Pass | H25: Fail | I25: N/A | J25: Blocker
E26: Practice Setup | F26: 234 | G26: =COUNTIF(PracticeManagement!I:I,"Pass") -> 0 | H26: =COUNTIF(PracticeManagement!I:I,"Fail") -> 0 | I26: =COUNTIF(PracticeManagement!I:I,"N/A") -> 0 | J26: =COUNTIF(PracticeManagement!I:I,"Blocker") -> 0
E27: Front Desk | F27: 444 | G27: =COUNTIF(FrontDesk!M:M,"Pass") -> 0 | H27: =COUNTIF(FrontDesk!M:M,"Fail") -> 0 | I27: =COUNTIF(FrontDesk!M:M,"N/A") -> 0 | J27: =COUNTIF(FrontDesk!M:M,"Blocker") -> 0
E28: Messaging | F28: 184 | G28: =COUNTIF(Message!M:M,"Pass") -> 0 | H28: =COUNTIF(Message!M:M,"Fail") -> 0 | I28: =COUNTIF(Message!M:M,"N/A") -> 0 | J28: =COUNTIF(Message!M:M,"Blocker") -> 0
E29: Nurse | F29: 459 | G29: =COUNTIF(Nurse!K:K,"Pass") -> 0 | H29: =COUNTIF(Nurse!K:K,"Fail") -> 0 | I29: =COUNTIF(Nurse!K:K,"N/A") -> 0 | J29: =COUNTIF(Nurse!K:K,"Blocker") -> 0
E30: Billing | F30: 806 | G30: =COUNTIF(Billing!L:L,"Pass") -> 0 | H30: =COUNTIF(Billing!L:L,"Fail") -> 0 | I30: =COUNTIF(Billing!L:L,"N/A") -> 0 | J30: =COUNTIF(Billing!L:L,"Blocker") -> 0
E31: Provider | F31: 398 | G31: =COUNTIF(Provider!I:I,"Pass") -> 0 | H31: =COUNTIF(Provider!I:I,"Fail") -> 0 | I31: =COUNTIF(Provider!I:I,"N/A") -> 0 | J31: =COUNTIF(Provider!I:I,"Blocker") -> 0
E32: New calendar | F32: 249 | G32: =COUNTIF(NewCalendar!I:I,"Pass") -> 0 | H32: =COUNTIF(NewCalendar!I:I,"Fail") -> 0 | I32: =COUNTIF(NewCalendar!I:I,"N/A") -> 0 | J32: =COUNTIF(NewCalendar!I:I,"Blocker") -> 0
E33: Total | F33: =SUM(F26:F32) -> 2774

Sheet Split
C2: Release Type | D2: FB | E2: MySQL
C3: Feature Release | D3: High-Level Testing | E3: Full Regression Testing
C4: Maintenance Release | D4: High-Level Testing | E4: High-Level Testing
C9: Feature Release
C11: Team Member | D11: High Level Count | E11: High Level Module | F11: Full Regression Count | G11: Full Regression Module | H11: Total TC count
C12: Marcelo | D12: 64 | E12: Front Desk | F12: 143 | G12: Front Desk | H12: =sum(D12+F12) -> 207
C13: Walter | D13: 71 | E13: Front Desk | F13: 147 | G13: Front Desk | H13: =sum(D13+F13) -> 218
C14: Osmar | D14: 0 | E14: - | F14: 198 | G14: PM | H14: =sum(D14+F14) -> 198
C15: David | D15: 56 | E15: Message | F15: 185 | G15: Message | H15: =sum(D15+F15) -> 241
C16: Bruno | D16: 0 | E16: - | F16: 146 | G16: Front Desk | H16: =sum(D16+F16) -> 146
C17: Gustavo | D17: 60 | E17: Billing | F17: 160 | G17: Billing | H17: =sum(D17+F17) -> 220
C18: Thara | D18: 64 | E18: Nurse | F18: 135 | G18: Nurse | H18: =sum(D18+F18) -> 199
C19: Shalini | D19: 64 | E19: Nurse | F19: 135 | G19: Nurse | H19: =sum(D19+F19) -> 199
C20: Hari | D20: 0 | E20: - | F20: 249 | G20: New calendar | H20: =sum(D20+F20) -> 249
C21: New1 | D21: 0 | E21: - | F21: 133 | G21: Nurse | H21: =sum(D21+F21) -> 133
C22: Praveen | D22: 79 | E22: New calendar | F22: 100 | G22: Provider | H22: =sum(D22+F22) -> 179
C23: Darshan | D23: 63 | E23: Provider | F23: 99 | G23: Provider | H23: =sum(D23+F23) -> 162
... C28: Manjunath | D28: 69 | E28: PM | F28: 99 | G28: Provider | H28: =sum(D28+F28) -> 168

Sheet FrontDesk
A1: TEST SCENARIO | B1: STEPS | C1: EXPECTED RESULTS | D1: TC source | E1: HighLevel | F1: Owner - FB(High level) | G1: Status | H1: Comment | I1: Owner - MySQL(Full regression) | J1: Status | K1: Comments
A2: Login: Show a popup when the user enters the wrong password
A3: Verify below warning popup shows up, when user login OP with wrong username and password. "Incorrect username and password". | B3: 1. Open the OP application. 2. Enter wrong Username and Password. 3. Click Login button. 4. Check below warning popup shows up, when user login OP with wrong username and password. "Incorrect username and password". | C3: Below warning popup should shows up. "Incorrect username and password". | D3: Insprint | E3: Yes | F3: Marcelo | I3: Marcelo
A4: Verify below warning popup shows up, when user login OP with wrong username and correct password. "Incorrect username and password". | B4: 1. Open the OP application. 2. Enter wrong Username and correct Password. 3. Click Login button. 4. Check below warning popup shows up, when user login OP with wrong username and correct password. "Incorrect username and password". | C4: Below warning popup should shows up. "Incorrect username and password". | D4: Insprint | E4: Yes | F4: Walter | I4: Walter
A5: Verify below warning popup shows up, when user login OP with correct username and wrong password. "Incorrect username and password". | B5: 1. Open the OP application. 2. Enter correct Username and wrong Password. 3. Click Login button. 4. Check below warning popup shows up, when user login OP with correct username and wrong password. "Incorrect username and password". | C5: Below warning popup should shows up. "Incorrect username and password". | D5: Insprint | E5: Yes | F5: Marcelo | I5: Marcelo
A6: Verify below warning popup shows up, when user enters special characters in username and password to login OP. "Incorrect username and password". | B6: 1. Open the OP application. 2. Enter special characters in Username and Password. 3. Click Login button. 4. Check below warning popup shows up, when user enters special characters in username and password to login OP. "Incorrect username and password". | C6: Below warning popup should shows up. "Incorrect username and password". | D6: Insprint | E6: Yes | F6: Walter | I6: Walter
A7: Verify the cursor is auto-focused(i.e. cursor should placed in the username box) in the username box. when user login OP with wrong username and password and accepts the warning popup "Incorrect username and password" . | B7: 1. Open the OP application. 2. Enter wrong Username and Password. 3. Click Login button. 4. The "Incorrect username and password" waring popup shows up. 5. Accept the warning popup. 6. Check the cursor is auto-focused(i.e. cursor should placed in the username box) in the username box. | C7: The cursor should auto-focused(i.e. cursor should placed in the username box) in the username box. | D7: Insprint | E7: Yes | F7: Marcelo | I7: Marcelo
A8: Login box should not disappear, when user clicks on cancel button. | B8: 1. Open the OP application. 2. Enter Username and Password. 3. Click Cancel button instead of clicking Login button. 4. Check Login box should not disappear, only the data entered in username and password should disappear. | C8: Login box should not disappear, only the data entered in username and password should be disappear. | D8: RelaseFilter | E8: Yes | F8: Walter | I8: Walter
A9: Verify the choose location pop window has been displayed, when user try to login the application for first time in a day. | B9: First time in a day 1. Launch the op application 2. enter the user name and password 3. Click login button 4. Check the Choose location pop up window is popup. 5. Select the valid location and click ok button. | C9: Choose Location pop up window should be displayed | D9: Exploratory | I9: Marcelo
A10: Verify the choose location pop window is not displayed, when the same user try to login the application for second time in a day. | B10: Second time in a day 1. Launch the op application 2. without enter the user name and password 3. Click login button 4. Observe Choose location pop window will not come for second time login in a day 5. Navigate to dashboard | C10: Choose Location pop window should not displayed for second time login in a day | D10: Exploratory | I10: Walter
A11: Verify user able to select the location | B11: First time in a day 1. Launch the op application 2. enter the user name and password 3. Click login button 4. Check the Choose location pop up window is popup. 5. Select the valid location and click ok button. | C11: Application should be launched the home page | D11: Exploratory | I11: Marcelo
A12: Verify user not able to access the dashboard without selecting any location | B12: Location popup will come only first time in a day 1. Launch the op application 2. without enter the user name and password 3. Click login button 4. location pop up window will come 4. Not selecting the location 5. Click cancel button. 6. Check the user not able to login and user remains to login page . | C12: Application should be throw an error message and reopen the login page window. | D12: Exploratory
A13: Access and Navigate to the schedule Window
A14: Verify user able to access the schedule window by clicking on schedule icon | B14: 1. launch the OP application 2. Select the clinical tab in the top-left corner of the window. 3. Click Schedule Icon. | C14: Schedule Window should appear. | E14: Yes | F14: Marcelo | I14: Marcelo
A15: Verify user can able to view appointment window | B15: 1. Login to the OP 2. Navigate to Practice Management > Schedule > calender window 3. Double click to add an appointment 4. Check user able to view the appointment window | C15: User should view the appointment window | D15: Insprint | I15: Walter
A16: Verify "Prim/alt phone" is removed | B16: 1. Login to the OP 2. Navigate to Practice Management > Schedule > calender window 3. Double click to add an appointment 4. Ensure the appointment window open 5. Check there is no "Prim/alt phone:" field | C16: User should not view "Prim/alt phone:" field | D16: Insprint | I16: Marcelo
A17: Verify Curbside has been left aligned | B17: 1. Login to the OP 2. Navigate to Practice Management > Schedule > calendar window 3. Double click to add an appointment 4. Ensure"Curbside" field located in left side | C17: User should view the "Curbside" field located in left side | D17: Insprint | I17: Marcelo
A18: Verify user can able to view new patient header | B18: 1. Login to the OP. 2. Navigate to Practice Management > Schedule > calender window. 3. Double click to add an appointment. 4. Check the appointment window visible. 5. Search a patient. 6. Check user can able to view the new patient header. | C18: User should view the new patient header | D18: Insprint | I18: Marcelo
A19: Verify user can able to view pencil button next to the patient name | B19: 1. Login to the OP 2. Navigate to Practice Management > Schedule > calender window 3. Double click to add an appointment. 4. Ensure the add appointment window visible. 5. Search a patient. 6. Check user can able to view pencil button is visible. | C19: User should view pencil button. | D19: Insprint
A20: Verify user can see the correct placement of the Search button, Last encounter, Last well visit, and Portal Account information | B20: 1. Login to the OP 2. Navigate to Practice Management > Schedule > calender window 3. Double click to add an appointment 4. Ensure the add appointment window visible 5. Search a patient 6. Cheeck user able to see the correct placement of the Search button, Last encounter, Last well visit, and Portal Account information | C20: User should see the correct placement of the Search button, Last encounter, Last well visit, and Portal Account information | D20: Insprint | I20: Marcelo
A21: Verify user can see labels above the Misc. Notes and Billing Notes grid | B21: 1. Login to the OP 2. Navigate to Practice Management > Schedule > calender window 3. Double click to add an appointment 4. Ensure the add appointment window visible 5. Check user can view the labels above the Misc. Notes and Billing Notes grid | C21: User should see the labels above the Misc. Notes and Billing Notes grid. | D21: Insprint | I21: Marcelo
A22: Verify user can abe to see the Blank Patient Photo | B22: 1. Login to the OP 2. Navigate to Practice Management > Schedule > calender window 3. Double click to add an appointment 4. Check the add appointment window visible 5. Search a patient 6. Check user can view the Blank Patient Photo. | C22: User should view the Blank Patient Photo. | D22: Insprint | I22: Marcelo
A23: Verify User can able to view 2 radio button options "Patient" and "Family Contact" on full patient search window | B23: 1.Log into OP 2. Navigate to Clinical > Practice Management > Billing 3. Click the patient chart 4. Click the Full Search Icon(Patient Finder icon) make sure the full patient search window is opened 5. look at the top of the window 6. Make sure the user can see 2 radio button options 'Patient' and 'Family Contact' | C23: User should view 2 radio button options "Patient" and "Family Contact" on full patient search window | D23: RelaseFilter | I23: Bruno
A24: Verify Patient radio button is selected by default on full patient search window. | B24: 1. Log into OP 2. Navigate to Clinical > Practice Management > Billing 3. Click the patient chart 4. Click the Full Search Icon(Patient Finder icon) make sure the full patient search window is opened 5. look at the top of the window 6. Make sure the user can see Patient radio button is selected by default | C24: The Patient radio button should selected by default on full patient search window. | D24: RelaseFilter | I24: Bruno
A25: Verify User can able to Search for a patient by using the Patient Radio Button for the below-mentioned field on the full patient search window and verify the grid displays searched patient. Last Name First Name DOB PatNo Alt phone | B25: 1. Log into OP 2. Navigate to Clinical > Practice Management > Billing 3. Click the patient chart 4. Click the Full Search Icon(Patient Finder icon) make sure the full patient search window is opened 5. Make sure the patient radio button is selected in the full patient search window 6. Enter In the (Last Name, First Name, DOB, PatNo, Alt, phone )search criteria 7. Make sure the results of patients meet the criterion selected. | C25: User Should search a patient by using the Patient Radio Button for the below-mentioned field on the full patient search window and the grid should displays searched patient. Last Name First Name DOB PatNo Alt phone | D25: RelaseFilter | I25: Bruno
A26: Verify that when the "Family Contact" radio button is selected, the "PatNo", "DOB", and "Alt Name" fields are disabled on the full patient search window. | B26: 1. Log into OP 2. Navigate to Clinical > Practice Management > Billing 3. Click the patient chart 4. Click the "Full Search" icon to ensure the full patient search window is opened 5. Ensure the "Family Contact" radio button is selected in the full patient search window 6. Review the search criteria fields 7. Confirm that the "PatNo", "DOB", and "Alt. Name" fields are disabled as they are not applicable to Family Contact | C26: Users should observe that the "PatNo", "DOB", and "Alt. Name" fields are disabled on the full patient search window when the "Family Contact" radio button is selected. | D26: RelaseFilter | I26: Bruno
A27: Verify that the user can search for a patient using the "Family Contact" radio button for the following fields on the full patient search window and confirm that the grid displays the searched patient: - Last Name - First Name - Phone | B27: 1. Log into OP 2. Navigate to Clinical > Practice Management > Billing 3. Click the patient chart 4. Click the "Full Search" icon (Human icon) to ensure the full patient search window is opened 5. Ensure the "Family Contact" radio button is selected in the full patient search window 6. Enter the search criteria for (Last Name, First Name, Phone) 7. Confirm that the results display patients with linked family contacts meeting the selected criteria | C27: User should search for a patient by using the "Family Contact" radio button for the following fields on the full patient search window and verify the grid displays patients with linked family contacts meeting the selected criteria: - Last Name - First Name - Phone | D27: RelaseFilter | I27: Bruno
A28: Verify that the user can save the "Family Contact" radio button as a preference on the full patient search window. | B28: 1. Log into OP 2. Navigate to Clinical > Practice Management > Billing 3. Click the patient chart 4. Click the "Full Search" icon (Patient Finder icon) to ensure the full patient search window is opened 5. Select the "Family Contact" Radio Button in the full patient search window 6. Click "Save Preference" 7. Close and reopen the OP application 8. Verify that the "Family Contact" radio button is selected by default | C28: User should save the "Family Contact" Radio Button as a preference on the full patient search window. | D28: RelaseFilter | I28: Bruno
A29: Verify the functionality of the alphabet tabs to match the current functionality on the full patient search window. | B29: 1. Log into OP 2. Navigate to Clinical > Practice Management > Billing 3. Click the patient chart 4. Click the "Full Search" icon (Human icon) to ensure the full patient search window is opened 5. Select the "Family Contact" radio button in the full patient search window 6. Click any of the alphabet buttons at the bottom of the window 7. Verify that only patients with linked family contacts, whose last names begin with the pressed letter, are displayed in the search window | C29: The functionality of the alphabet tabs should match the current functionality on the full patient search window. | D29: RelaseFilter | I29: Bruno
A30: Verify user can Search results for family contact on the full patient search window | B30: 1. Log into OP 2. Navigate to Clinical > Practice Management > Billing 3. Click the patient chart 4. Click the "Full Search" icon (Patient Finder icon) to ensure the full patient search window is opened 5. Select the "Family Contact" radio button in the full patient search window 6. Search using any enabled search criteria fields 7. Verify that patients with linked family contacts meeting the selected criteria are shown first, followed by patients who meet the criteria in the list of results | C30: User should search results for family contact on the full patient search window. | D30: RelaseFilter | I30: Bruno
A31: Verify that entering 10 digits and hitting ENTER shows all phone numbers meeting that criteria, regardless of whether dashes are stored or not in the Patient database. | B31: 1. Log into OP 2. Open Patient Chart 3. Click the Search Icon to open the advanced search 4. Select the "Patient" radio button 5. Enter a 10-digit phone number 6. Press ENTER 7. Verify that all patients with the entered 10-digit phone number are displayed, regardless of whether there are hyphens or not. | C31: The user should press ENTER and view 10 digits of phone numbers meeting that criteria, regardless of whether dashes are stored or not in the Patient database. | D31: RelaseFilter | I31: Bruno
... A68: Verify that the user can see an alert on save when the Phone field is blank but an Extension exists on Demographics. NOTE - Repeat for Family Contacts | B68: 1. Log in to the OP application. 2. Navigate to any one of the tabs Clinical / Practice Management / Billing. 3. Select a patient's chart. 4. Go to Basic Information to open the Demographics. 5. Look next to Day/Work; you see a small extension field. 6. Enter an Extension and no Day/Work number. 7. Click Save. 8. Verify you get an alert: "Day/Work number is required when an extension is present." NOTE - Repeat for Family Contacts | C68: User should see an alert on Save when the Phone field is blank but Extension exists on Demographics. NOTE - Repeat for Family Contacts | D68: Insprint | I68: Bruno
A69: Check if the shortcut key "Function + F7" opens the schedule window. | B69: 1. Launch the OP application. 2. Select the Clinical tab. 3. Press the F7 key. | C69: The Schedule Window should appear. | I69: Walter
A70: Verify that the No Show* Billing Status does not add a Miscellaneous Note. | B70: 1. Launch OP. 2. Open the Schedule. 3. Schedule an appointment. 4. Click Save. 5. Double click on the appointment to edit. 6. Click the Billing Status dropdown. 7. Select 'No Show*'. 8. Click Save. 9. Open the Patient's chart. 10. Open Clinical Overview. 11. Verify they do not see a miscellaneous note stating "@No Show- Today's Date". | C70: User should not be able to add a Miscellaneous Note by using the No Show* Billing Status. | D70: Insprint | I70: Walter
A71: Verify that the No Show Billing Status does add a Miscellaneous Note. | B71: 1. Launch OP. 2. Open the Schedule. 3. Schedule an appointment. 4. Click Save. 5. Double click on the appointment to edit. 6. Click the Billing Status dropdown. 7. Select 'No Show'. 8. Click Save. 9. Open the Patient's chart. 10. Open Clinical Overview. 11. Verify they do see a miscellaneous note stating "@No Show- Today's Date". | C71: User should be able to see a miscellaneous note stating '@No Show- Today's Date'. | D71: Insprint | I71: Walter
A72: Verify that when one user is scheduling an appointment, another user should see a 'Scheduling in progress' bar on the time slot. | B72: 2 different users need to be logged into OP to test. Both users: 1. Log into OP. 2. Open the Calendar schedule for Demo Doctor. User 1: 1. Double click on a time slot to open the Add/Edit appointment window. User 2: 1. User 2 should see a "Scheduling in progress" bar on the time slot where an appointment is being scheduled. NOTE- Try with 3-5 other users logged in as well to make sure all users see the "Scheduling in progress" bar. | C72: Users should see that when one user is scheduling an appointment, another user should see the "Scheduling in progress" bar on the time slot. | D72: RelaseFilter | I72: Marcelo
A73: Verify that when one user adds an appointment to the schedule, all other users can see the 'appointment' on the same day and provider in the calendar schedule. | B73: 2 different users need to be logged into OP to test. Both users: 1. Log into OP. 2. Open the Calendar schedule for Demo Doctor. User 1: 1. Double click on a time slot to open the Add/Edit appointment window. 2. Finish scheduling appointment and click Save. User 2: 1. User 2 should see a "Scheduling in progress" bar on the time slot where an appointment is being scheduled. 2. User 2 should see the appointment appear on the schedule. | C73: Users should see that when one user adds an appointment to the schedule, all other users should see the 'appointment' on the same day and provider in the calendar schedule. | D73: RelaseFilter | I73: Marcelo
A74: Verify that when one user updates the visit status on an appointment, other users see the appointment block color update on the schedule. | B74: 2 different users need to be logged into OP to test. Both users: 1. Log into OP. 2. Open the Calendar schedule for Demo Doctor. User 1: 1. Schedule an appointment and close the Add/Edit appointment window. User 2: 1. User 2 should see a "Scheduling in progress" bar and the appointment appear on the time slot where an appointment is being scheduled. User 1: 1. Double click on the appointment and update the visit status. 2. Save and Exit. User 2: 1. User 2 should see that the appointment color changes based on the appointment status chosen. NOTE - Try with 3-5 other users logged in as well to make sure all users see the appointment update. | C74: When one user updates the visit status on an appointment, verify that other users see the appointment block color update on the schedule. | D74: RelaseFilter | I74: Marcelo
A75: Verify that when one user adds a copay in the Add/Edit appointment window, other users see the copay label on the appointment on the schedule. | B75: 2 different users need to be logged into OP to test. Both users: 1. Log into OP. 2. Open the Calendar schedule for Demo Doctor. User 1: 1. Schedule an appointment and close the Add/Edit appointment window. User 2: 1. User 2 should see a "Scheduling in progress" bar and the appointment appear on the time slot where an appointment is being scheduled. User 1: 1. Double click on the appointment and click on the credit button next to the Payment Received field. 2. Enter the payment information (Payment method, Patient amount). 3. Click Save/Post. User 2: 1. User 2 should see that the appointment is updated with the Copay box. NOTE - Try with 3-5 other users logged in as well to make sure all users see the appointment update. | C75: When one user adds a copay in the Add/Edit appointment window, other users should see the copay label on the appointment on the schedule. | D75: RelaseFilter | I75: Marcelo
A76: 1) Verify that when one user adds the flags (WHITE, GREEN, RED) to an appointment, all other users are able to see the flags (WHITE, GREEN, RED) on the same day and provider in the calendar schedule. 2) "Verify that when one user removes the flags (WHITE, GREEN, RED) from an appointment, the flags (WHITE, GREEN, RED) have been removed from the appointment for all other users on the same day and provider in the calendar schedule. | B76: 2 different users need to be logged into OP to test. Both users: 1. Log into OP. 2. Open the Calendar schedule for Demo Doctor. User 1: 1. Schedule an appointment and close the Add/Edit appointment window. User 2: 1. User 2 should see a "Scheduling in progress" bar and the appointment appear on the time slot where an appointment is being scheduled. User 1: 1. Click on the appointment and click on the green flag. The green flag will appear on the appointment. 2. User 2 should see that the appointment is updated with the green flag. User 1: 1. Click on the appointment and click on the blank flag. The green flag will disappear from the appointment. 2. User 2 should see that the appointment is updated with the removal of the green flag. User 1: 1. Click on the appointment and click on the red flag. The red flag will appear on the appointment. 2. User 2 should see that the appointment is updated with the red flag. User 1: 1. Click on the appointment and click on the blank flag. The red flag will disappear from the appointment. 2. User 2 should see that the appointment is updated with the removal of the red flag. NOTE - Try with 3-5 other users logged in as well to make sure all users see the appointment update. | C76: 1) When one user adds the flags (WHITE, GREEN, RED) to an appointment, all other users should see the flags (WHITE, GREEN, RED) on the same day and provider in the calendar schedule. 2) When one user removes the flags (WHITE, GREEN, RED) from an appointment, the flags (WHITE, GREEN, RED) should be removed from the appointment for all other users on the same day and provider in the calendar schedule. | D76: RelaseFilter | I76: Marcelo
...

Sheet Billing
A1: TEST SCENARIO | B1: STEPS | C1: EXPECTED RESULTS | D1: HighLevel | E1: Owner - FB(High level) | F1: Status | G1: Comment | H1: Owner - MySQL(Full regression) | I1: Status | J1: Comment
A2: Billing - Setup
A3: Verify user able to access the Diagnosis code management window. | B3: 1.Launching the application 2.Enter the valid credential and click login button 3.Click the anyone of tab clinical, billing and access the Diagnosis code button 4.Make sure the diagnosis management window is getting popped up. | C3: Diagnosis Management window should popped up while clicks on Diagnosis code in billing tab. | D3: Yes | E3: Gustavo | H3: Gustavo
A4: Verify user able to add new diagnosis code | B4: 1.Launching the application 2.Enter the valid credential and click login button 3.Click the anyone of tab clinical, billing and access the Diagnosis code button 4.Access the diagnosis management window opened 5.Click the New button and The Diagnostic Code Editor window is displayed. 6.Enter the information and save the new diagnosis. | C4: New diagnosis code should be added. | D4: Yes | E4: Gustavo | H4: Gustavo
A5: Verify user able to edit the diagnosis code | B5: 1.Launching the application 2.Enter the valid credential and click login button 3.Click the anyone of tab clinical, billing and access the Diagnosis code button 4.Access the diagnosis management window opened 5.Search for the Diagnosis code to edit. 6.Click to select the Diagnosis Code. 7.Click the Edit button. 8.Edit the Diagnosis code using the table descriptions above. 9.Click the Save button. | C5: Diagnosis code should be edited | D5: Yes | E5: Gustavo | H5: Gustavo
A6: Verify the error popup will shown while adding a new diagnosis code without code set value | B6: 1.Launching the application 2.Enter the valid credential and click login button 3.Click the anyone of tab clinical, billing and access the Diagnosis code button 4.Access the diagnosis management window opened 5.Click the New button and The Diagnostic Code Editor window is displayed. 6.Add a diagnosis code without code set value. 7.Click on Save button. 8."Code set is a required field" error popup should appear. | C6: "Code set is a required field" error popup should be displayed while adding a new diagnosis code without code set value | D6: Yes | E6: Gustavo | H6: Gustavo
A7: Verify the opened diagnostic code editor window is closed after clicking the cancel button | B7: 1.Launching the application 2.Enter the valid credential and click login button 3.Click the anyone of tab clinical, billing and access the Diagnosis code button 4.Access the diagnosis management window opened 5.Click the New button and access the Diagnostic Code Editor window opened 6.Click on Cancel button | C7: Opened window should be closed after clicking the cancel button | D7: Yes | E7: Gustavo | H7: Gustavo
A8: Verify user able to search the diagnosis code by clicking any alphabets at the bottom of the page | B8: 1.Launching the application 2.Enter the valid credential and click login button 3.Click the anyone of tab clinical, billing and access the Diagnosis code button 4.Access the diagnosis management window opened 5.Select the "Complete" radio button and click any one alphabets at the bottom of the page. 6.verify the searched alphabet diagnosis codes are listed in your search | C8: Searched diagnosis code should be displayed | D8: Yes | E8: Gustavo | H8: Gustavo
A9: Verify user able to search the diagnosis code with below option Search for the diagnosis code to map: Enter the search criteria (Code or Description). Select the correct Result Set radio button. Click the Search button. | B9: 1.Launching the application 2.Enter the valid credential and click login button 3.Click the anyone of tab clinical, billing and access the Diagnosis code button 4.Access the diagnosis management window opened 5.Search for the Diagnosis code and verify the searched diagnosis are listed in your search | C9: Searched diagnosis code should be displayed | D9: Yes | E9: Gustavo | H9: Gustavo
A10: Verify user able to print the diagnosis code | B10: 1.Launching the application 2.Enter the valid credential and click login button 3.Click the anyone of tab clinical, billing and access the Diagnosis code button 4.Access the diagnosis management window opened 5.Search for the Diagnosis code to print or click any alphabet letters at the bottom of the page. 6.Click on print button. | C10: Diagnosis code should be displayed in print preview page. | D10: Yes | E10: Gustavo | H10: Gustavo
A11: Verify user can ordering the diagnosis code by using sort number | B11: 1.Launching the application 2.Enter the valid credential and click login button 3.Click the anyone of tab clinical, billing and access the Diagnosis code button 4.Access the diagnosis management window opened 5.Select the "Complete" radio button and click any one alphabets at the bottom of the page. 6.Select the first Diagnosis Code which are listed. 7.Click the Edit button. 8.Click the Sort Order field and edit the sort number by using dropdown values or manually entering the data. 9.Click the Save button. 10.Check whether the selected diagnosis code is listed by sortnumber. | C11: Diagnosis code should be listed by sort number | D11: Yes | E11: Gustavo | H11: Gustavo
A12: Verify user able to Editing a sort number for exist diagnosis code | B12: 1. Launching the application 2. enter the valid credential and click login button 3. Click the billing tab and access the diagnosis code button 4. Access the diagnosis codes window 5. Search for diagnosis codes in search field and select the diagnosis codes 6. Click the Edit button and edit the sort number in sort field. 7. click the save button | C12: Sort number should be edited for diagnosis codes | D12: Yes | E12: Gustavo | H12: Gustavo
A13: Verify user able to Deleting a Sort number for exist diagnosis code | B13: 1. Launching the application 2. enter the valid credential and click login button 3. Click the billing tab and access the diagnosis code button 4. access the diagnosis codes window 5. Search for diagnosis codes in search field and select the diagnosis codes 6. Click the Edit button and click in the sortfield and delete the text of the sort that you do not want. 7. click the save button | C13: Sort number should be deleted for diagnosis codes | D13: Yes | E13: Gustavo | H13: Gustavo
A14: Verify user able to add new category for diagnosis code | B14: 1.Launching the application 2.Enter the valid credential and click login button 3.Click the anyone of tab clinical, billing and access the Diagnosis code button 4.Access the diagnosis management window opened 5.Search for the Diagnosis code to edit. 6.Click to select the Diagnosis Code. 7.Click the Edit button. 8.Click on Category field and clear the category name. 9.Type the new category name in the Category field 10.Click on Save button. 11.Click on yes button in confirm popup window. 12.Check whether the Category field should be edited for searched diagnosis code 13.Click the Edit button. 14.Click on Category field dropdown. 15.Check whether the newly created category name is listed in Category field dropdown and You will now be able to search for this code under the category. | C14: Newly created category name should be listed in Category field dropdown | D14: Yes | E14: Gustavo | H14: Gustavo
... A16: Verify user able to assigning the synonym for the diagnosis code | B16: 1. Launching the application 2. Enter the valid credential and click login button 3. Click the anyone of tab clinical, billing and access the Diagnosis code button 4. Access the diagnosis management window opened. 5. Search for the Diagnosis code and verify the searched diagnosis are listed in your search 6. Select the searched diagnosis and click the edit button 7. Diagnosis code edit window will open and select synonym tab 8. Click the Insert record button at the bottom of the window to add a new synonym. Once added, click the green check mark to save. 9. You will now be able to search for this code under the synonym. | C16: New synonym should be added for diagnosis code and User should be searched the diagnosis code using it's synonym | D16: Yes | E16: Gustavo | H16: Gustavo
A17: Verify user able to edit the synonym for the diagnosis code | B17: 1. Launching the application 2. Enter the valid credential and click the login button 3. Click the anyone of tab clinical, billing and access the Diagnosis code button 4. Access the diagnosis management window opened. 5. Search for the Diagnosis code and verify the searched diagnosis are listed in your search 6. Select the searched diagnosis and click the edit button 7. Diagnosis code edit window will open and select the synonym tab 8. Select the synonym which you want to edit. 9. Click the Edit icon at the bottom of the window and edit that. 10. Once edited, click the green check mark to save. 11. check whether the selected synonym is edited in the synonyms tab. | C17: Selected synonym should be edited | H17: Gustavo
A18: Verify user able to delete the synonym for the diagnosis code | B18: 1. Launching the application 2. Enter the valid credential and click login button 3. Click the anyone of tab clinical, billing and access the Diagnosis code button 4. Access the diagnosis management window opened. 5. Search for the Diagnosis code and verify the searched diagnosis are listed in your search 6. Select the searched diagnosis and click the edit button 7. Diagnosis code edit window will open and select synonym tab 8. Select the synonym which you want to delete. 9. Click the delete icon at the bottom of the window. 10.Click on ok button in confirm popup window. 11.check whether the selected synonym is not displayed in synonyms tab. | C18: Selected synonym should be deleted | D18: Yes | E18: Gustavo | H18: Gustavo
A19: Verify user able to assigning the groups of diagnosis code | B19: 1.Launching the application 2.Enter the valid credential and click login button 3.Click the anyone of tab clinical, billing and access the 1. Launching the application 2. Enter the valid credential and click login button 3. Click the anyone of tab clinical, billing and access the Diagnosis code button 4. Access the diagnosis management window opened. 5. Search for the Diagnosis code and verify the searched diagnosis are listed in your search 6. Select the searched diagnosis and click the edit button 7. Diagnosis code edit window will open and select the synonym tab 8. Select the synonym which you want to edit. 9. Click the Edit icon at the bottom of the window and edit that. 10.Once edited, click the green check mark to save. 11.check whether the selected synonym is edited in synonyms tab. code button 4.Access the diagonsis management window opened. 5.Search for the Diagnosis code and verify the searched diagnosis are listed in your search 6.Select the searched diagnosis and click the edit button 7.Diagnosis code edit window will open and select Diagnostic group tab 8.Click the Insert record button at the bottom of the window to add a new Diagnostic Group. Once added, click the green check mark to save. 9.You will now be able to search for this code under the diagnostic group. | C19: New diagnostic group should be added | D19: Yes | E19: Gustavo | H19: Gustavo
A20: Verify user able to edit the group for the diagnosis code | B20: 1. Launching the application 2. Enter the valid credential and click login button 3. Click the anyone of tab clinical, billing and access the Diagonsis code button 4. Access the diagonsis management window opened. 5. Search for the Diagnosis code and verify the searched diagnosis are listed in your search 6. Select the searched diagnosis and click the edit button 7. Diagnosis code edit window will open and select Diagnostic groups tab 8. Select the goup which you want to edit. 9. Click the Edit icon at the bottom of the window and edit that. 10.Once edited, click the green check mark to save. 11.check whether the selected group is edited in diagnostic groups tab | C20: Selected group should be edited | H20: Gustavo
A21: Verify user able to delete the group for the diagnosis code | B21: 1. Launching the application 2. Enter the valid credential and click login button 3. Click the anyone of tab clinical, billing and access the Diagonsis code button 4. Access the diagonsis management window opened. 5. Search for the Diagnosis code and verify the searched diagnosis are listed in your search 6. Select the searched diagnosis and click the edit button 7. Diagnosis code edit window will open and select diagnostic groups tab 8. Select the group which you want to delete in diagnostic groups tab tab. 9. Click the delete icon at the bottom of the window. 10.Click on ok button in confirm popup window. 11.check whether the selected group is not displayed in Diagnostic groups tab. | C21: Selected group should be deleted | D21: Yes | E21: Gustavo | H21: Gustavo
A22: Verify user able to assign the "cross mappings" for diagnosis code. | B22: 1.Launching the application 2.Enter the valid credential and click login button 3.Click the anyone of tab clinical, billing and access the Diagonsis code button 4.Access the diagonsis management window opened. 5.Search for the Diagnosis code and verify the searched diagnosis are listed in your search 6.Select the searched diagnosis and click the edit button 7.Diagnosis code edit window will open and select the cross mappings tab 8.Click the Insert record button at the bottom of the window to add a new cross mappings. 9.Click the dropdown of mapped diagnosis field, the diagonsis management window is getting poped up 10.Enter the dx code in search field and click on search button. 11.Once added, click the green check mark to save. 12.check whether the newly created cross mappings is added in cross mappings tab | C22: New cross Mappings should be added. | D22: Yes | E22: Gustavo | H22: Gustavo
A23: Verify user able to edit the "cross mappings" for diagnosis code. | B23: 1. Launching the application 2. Enter the valid credential and click login button 3. Click the anyone of tab clinical, billing and access the Diagonsis code button 4. Access the diagonsis management window opened. 5. Search for the Diagnosis code and verify the searched diagnosis are listed in your search 6. Select the searched diagnosis and click the edit button 7. Diagnosis code edit window will open and select cross mappings tab 8. Select the cross mappings which you want to edit. 9. Click the Edit icon at the bottom of the window and edit that. 10.Once edited, click the green check mark to save. 11.check whether the selected cross mappings is edited in cross mappings tab | C23: Selected Cross Mappings should be edited | H23: Gustavo
A24: Verify user able to delete the "cross mappings" for diagnosis code. | B24: 1. Launching the application 2. Enter the valid credential and click login button 3. Click the anyone of tab clinical, billing and access the Diagonsis code button 4. Access the diagonsis management window opened. 5. Search for the Diagnosis code and verify the searched diagnosis are listed in your search 6. Select the searched diagnosis and click the edit button 7. Diagnosis code edit window will open and select cross mappings tab 8. Select the cross mappings which you want to delete 9. Click the delete icon at the bottom of the window. 10.Click on ok button in confirm popup window. 11.check whether the selected cross mappings is not displayed in cross mappings tab. | C24: Selected Cross Mappings should be deleted | D24: Yes | E24: Gustavo | H24: Gustavo
A25: Verify user able to access the CPT code management | B25: 1.Launching the application 2.enter the valid credential and click login button 3.Click the billing tab and access the procedure CPT code button 4.Check whether the user able to acces the procedure CPT codes window | C25: CPT code should be accessable | D25: Yes | E25: Gustavo | H25: Gustavo
A26: Verify the opened cpt code management window is closed after clicking the cancel button | B26: 1.Launching the application 2.Enter the valid credential and click login button 3.Click the anyone of tab clinical, billing and access the procedure CPT code button 4.Access the procedure CPT codes window opened 5.Click on Cancel button | C26: Opened Cpt code window should be closed after clicking the cancel button | D26: Yes | E26: Gustavo | H26: Gustavo
A27: Verify user able to search the CPT code using below search criteria "Frequently Used,Complete,Category," | B27: 1.Launching the application 2.enter the valid credential and click login button 3.Click the billing tab and access the CPT code button 4.access the CPT codes window 5.Search for the CPT code using search option and verify the searched CPT are listed in your search | C27: User can search the CPT code using search criteria. | D27: Yes | E27: Gustavo | H27: Gustavo
A28: Verify user able to add new CPT code | B28: 1.Launching the application 2.enter the valid credential and click login button 3.Click the billing tab and access the CPT code button 4.access the CPT codes window 5.Click edit button,The CPT-4: Physicians Current Procedural Terminology window opens. 6.Click the Add button enter the information 7.Click save button | C28: New CPT code should be added. | D28: Yes | E28: Gustavo | H28: Gustavo
A29: Verify user able to Edit CPT code | B29: 1.Launching the application 2.enter the valid credential and click login button 3.Click the billing tab and access the CPT code button 4.access the CPT codes window 5.Search for CPT codes in search box and select the CPT code you would like to edit. 6.Click the Edit button and make an necessary changes(description) 7.Click save button | C29: User can modify the CPT codes | D29: Yes | E29: Gustavo | H29: Gustavo
A30: Verify user able to Delete CPT code | B30: 1.Launching the application 2.enter the valid credential and click login button 3.Click the billing tab and access the CPT code button 4.access the CPT codes window 5.Search for CPT codes in search box and select the CPT code you would like to delete. 6.Click the delete button and click yes button to confirm 7.verify the cpt codes is deleted | C30: User can Delete the CPT codes | D30: Yes | E30: Gustavo | H30: Gustavo
A31: Verify that the user is not viewing '21310' and '33470' Delete the CPT code in the CPT codes window | B31: 1. Launching the application 2. Enter the valid credential and click the login button 3. Click the billing tab and access the CPT code button 4. Access the CPT codes window 5. Search for '21310' and '33470' Delete the CPT code in the search box Note: Ensure delete CPT code is not visible in the CPT codes window | C31: User ensure '21310' and '33470' Delete CPT code not visible in CPT codes window | H31: Gustavo
A32: Verify user able to view the fee schedule for the individual cpt codes | B32: 1.Launching the application 2.enter the valid credential and click login button 3.Click the billing tab and access the CPT code button 4.access the CPT codes window 5.Search for CPT codes in search box and select the cpt codes 6.view the fee schedule for the cpt codes | C32: User can view the CPT code fee schedule | D32: Yes | E32: Gustavo | H32: Gustavo
A33: Verify user able to edit the fee schedule for the individual cpt codes | B33: 1. Launching the application 2. enter the valid credential and click login button 3. Click the billing tab and access the CPT code button 4. access the CPT codes window 5. Search for CPT codes in search box and select the cpt codes 6. click in the appropriate Fee field and make your edits. 7. click the save button | C33: User can edit the CPT code fee schedule | D33: Yes | E33: Gustavo | H33: Gustavo
A34: Verify user able to copy the fee schedules for the individual cpt codes | B34: 1. Launching the application 2. enter the valid credential and click login button 3. Click the billing tab and access the CPT code button 4. access the CPT codes window 5. Search for CPT codes in search box and select the cpt codes 6. Click the Modify Fee Schedule button. 7. Fill out the equation as needed. 8. click Apply to save your changes. 9. Click Done to close the window.You will have to close the CPT code table and reopen it to see the changes. | C34: User can copy one fee schedules to another fee schedules | H34: Gustavo
A35: Verify user able to add new category for the CPT code | B35: 1. Launching the application 2. enter the valid credential and click login button 3. Click the billing tab and access the CPT code button 4. access the CPT codes window 5. Click edit button,The CPT-4: Physicians Current Procedural Terminology window opens. 6. Click the Edit button to edit the CPT Code. 7. Click in the Category field and Type the new Category name 8. Click the Save button. The new category will now be visible in the Category drop-down list when searching for CPT codes. | C35: User can add a new category | D35: Yes | E35: Gustavo | H35: Gustavo
A36: Verify user able to adding a category for exist CPT code | B36: 1. Launching the application 2. enter the valid credential and click login button 3. Click the billing tab and access the CPT code button 4. access the CPT codes window 5. Search for CPT codes in search box and select the cpt codes 6. Click the Edit button and Click the Category drop-down and select the appropriate category. 7. click the save button | C36: User can add a new category for the exist cpt codes | D36: Yes | E36: Gustavo | H36: Gustavo
A37: Verify user able to Editing a category for exist CPT code | B37: 1. Launching the application 2. enter the valid credential and click login button 3. Click the billing tab and access the CPT code button 4. access the CPT codes window 5. Search for CPT codes in search box and select the cpt codes 6. Click the Edit button and Click the Category drop-down and select the appropriate category. 7. click the save button | C37: User can edit a category | H37: Gustavo
A38: Verify user able to Deleting a category for exist CPT code | B38: 1. Launching the application 2. enter the valid credential and click login button 3. Click the billing tab and access the CPT code button 4. access the CPT codes window 5. Search for CPT codes in search box and select the cpt codes 6. Click the Edit button and click in the Category field and delete the text of the category that you do not want. 7. click the save button | C38: User can Delete a category | D38: Yes | E38: Gustavo | H38: Gustavo
A39: Verify user able to adding a sort number for exist CPT code | B39: 1. Launching the application 2. enter the valid credential and click login button 3. Click the billing tab and access the CPT code button 4. access the CPT codes window 5. Search for CPT codes in search box and select the cpt codes 6. Click the Edit button and Click the sort field and adding the sort 7. click the save button | C39: Sort number should be added for CPT codes | D39: Yes | E39: Gustavo | H39: Gustavo
A40: Verify user able to Editing a sort for exist CPT code | B40: 1. Launching the application 2. enter the valid credential and click login button 3. Click the billing tab and access the CPT code button 4. access the CPT codes window 5. Search for CPT codes in search box and select the cpt codes 6. Click the Edit button and edit the sort number in sort field. 7. click the save button | C40: Sort number should be edited for CPT codes | D40: Yes | E40: Gustavo | H40: Gustavo
A41: Verify the below mentioned CPT code is in the Complete List of the CPT code table i) 91304, ii) 0041A and iii) 0042A | B41: 1.Launching the application 2.Enter the valid credential and click login button 3.Click the billing tab and access the CPT code button 4.Access the CPT codes window 5.Select the "Complete List" radio button 6.Type the mentioned CPT code in search field and click "Search" button 7.Verify the mentioned CPT code are listed in the Complete List of the CPT code table | C41: Mentioned CPT code should be in the Complete List of the CPT code table | H41: Gustavo
...

Sheet Nurse
B1: STEPS | D1: Owner - FB(High level) | E1: Status | F1: Comment | G1: Owner - MySQL(Full regression) | H1: Status | I1: Comment
A3: Location
A4: Verify User Can Select and Change Location | B4: 1. Login as Nurse. 2. ✅ Verify that a location selection pop-up appears upon login. Note: The location selection pop-up appears only on the first login of the application. 3. ✅ Ensure the user can change the location based on assigned locations. 4. Navigate to the Clinical tab in the main panel. 5. Click on the Schedule icon to open the My View page in the calendar window. 6. Select the location from the calendar dropdown. 7. ✅ Verify that the user can successfully change the location in the calendar view based on assigned locations. | G4: Thara
A5: Clinical Tab Functionalities
A6: Verify User Can Able To Access Clinical Tab & its Functionalities | B6: 1.Login as Nurse. 2.Ensure the CLINICAL tab is displayed in the header section after login. 3.Click on the CLINICAL tab and ✅verify the following icons are displayed and accessible: 3.1. Patient Chart → Opens the Patient Chart. 3.2. Tasks → Opens the Tasks window. 3.3. Send Message → Opens the Send Message window. 3.4. Address Book → Opens the Address Book window. 3.5. Document Mgmt → Opens the Document Management window. 3.6. Medical Records → Opens the Medical Records window. 3.7. School/Camp Reports → Opens the Patient Medical Reports Manager. 3.8. Care Plans → Opens the Manage Care Plans: Global window. 3.9. Phrases → Opens the Phrase Construction window. 3.10. More - Diagnostic Tests → Opens the HL7 Diagnostic Test Utilities. 3.11. More - Graphical Milestones → Opens the Developmental Milestones Choice List. 3.12. More - Patient Education → Opens the AAP/Local Content Library. 3.13. More - Web/PDF Resources → Opens tabs for Web and PDF Resources. 3.14. More - Customize CDA → Opens the Customize CDA window. 3.15. Diagnosis Codes → Opens the Diagnosis Code Management window. 3.16. Procedure (CPT) Codes → Opens the CPT-4 window. 3.17. More - Allergy Codes → Opens the E-Prescriber Allergy Data mapping window. 3.18. More - Immunization Codes → Opens the Vaccine admin routes window. | C6: Yes | D6: Thara | G6: Thara
A7: Appointment
A8: Verify user able to schedule a new appointment (sick visit, well visit, PPD visit, PPD reading, placeholder, nurse visit) for a patient in the schedule window. | B8: 1.Login as Nurse. 2.Select the "Clinical" tab in the top-left corner of the window. 3.Click on the "Schedule" icon. 4.Select "My View" option and click the location dropdown (i.e.,Down arrow). 5.Choose the primary location. 6.Choose the time slot and double-click on the slot. 7.The "Add/Edit Appointment" window will be displayed. 8.Search for the patient in the search box and click the search icon. 9.✅Verify that the patient information is listed in the respective dropdowns. 10.Fill in the required fields, including: 10.1. Appointment Reason (Sick Visit, Well Visit, PPD Visit, Nurse Visit) 10.2. Appointment Type 11.Click the "Save" button. 12.✅Verify that the new appointment appears in the scheduled time slot. | C8: Yes | D8: Thara | G8: Thara
A9: Verify the User Can Open the Well Visit, from Tracking Window or Calendar Window | B9: 1. Log in as a Nurse. 2. Click the Schedule icon and navigate to the My View page. 3. Perform one of the following actions to open the Well Visit: 3.1. Select a scheduled patient appointment and right-click using the mouse. 3.2. Click on the Menu icon in the Tracking window and select Open Well Visit. 3.3. Right-click on the scheduled patient appointment in the Calendar and select Open Well Visit. 4. ✅ Ensure that the Interval HX tab opens successfully. | C9: Yes | D9: Thara | G9: Thara
A10: Verify the Confirmation Prompt and template in Well visit/Encounter note Confirmation Prompt Messages: In Encounter: The app is associated with template named. Would you like to apply this template In Well visit: Do you wish to use the default template for age? | B10: 1. Log in as a Nurse. 2. Click the Schedule icon and navigate to the My View page. 3. Right-click on the patient appointment in the Tracking window and select Open Well Visit/Open Encounter. 4. ✅ Check the confirm popup window is displayed. 4.1. Click the "NO" button 4.1.1. In Well Visit → ✅ Check that a new template is displayed (the associated template with the appointment should not appear in the Interval History info; it should display a blank template). 4.1.2. In Encounter → ✅ Check that a new template is displayed (the associated template with the appointment should not appear in the CC info; it should display a blank template). 4.2. Click the "YES" button 4.2.1. In Well Visit → ✅ Check that the associated template with the appointment is displayed in the Interval History info of the Well Visit note. 4.2.2. In Encounter → ✅ Check that the associated template with the appointment is not displayed in the CC info of the Encounter note. | C10: Yes | D10: Thara | G10: Thara
A11: Verify the appointments (without Appt reason and Appt type) should not be listed in the tracking window. | B11: 1.Login as Nurse 2.Navigate to schedule window using Clinical icon 3.Create an appointment without Appt reason nor Appt type 4.✅Verify user able to create appointment withou Appt reson nor Appt type. 5.Navigate to tracking window by clicking on Tracking radio button 6.✅Created appointment should not be displayed | C11: Yes | D11: Thara | G11: Thara
A12: Schedule - Tracking
A13: Verify User Can Able To Access Tracking Window and Related Functionalities . | B13: 1. Login as Nurse. 2. Click on the Schedule icon. 3. ✅ Verify that the "My View" screen is accessible. 4. Click on the Tracking Window and verify the following actions can be performed: 4.1. ✅ Ensure that the Tracking Window displays the following columns: \[Staff Name, Time, Patient, Reason, TOV, Arrival, Room, Visit Status, Min, Tasks, Billing Status, Ins. Valid, Verification #, Check Out, Pat Pay, Confirm Status, Curbside Status]. 4.2. ✅ Check if the logged-in staff name and the list of assigned patients appear in the Tracking View. 4.3. ✅ Verify that the user can drag the following columns in and out of the sort header: \[Staff, Patient, Reason, TOV, Arrival, Room, Visit Status, Billing Status, Curbside Status, Portal Account]. 4.4. ✅ Date Selection → The user can manually type or select a date from the calendar to view patient appointments for a specific date. 4.5. ✅ Show Tasks Filter → Selecting All, Mine, or Selected Department should update the Tasks column accordingly. 4.6. ✅ Expand/Collapse Grid → Checking/unchecking Expand Grid should show/hide entries. 4.7. ✅ Auto Refresh → Enabling Auto Refresh should keep the window updated in real time. 4.8. ✅ Exclude Checked Out → Checking this option should hide patients who have checked out. 4.9. ✅ Exclude Not Checked In → Checking this option should hide patients who have not checked in. 4.10. ✅ Show Billing Panel → Checking this should display billing transactions or superbill entries. 4.11. ✅ Print Tracking Schedule → Clicking Print should open a print preview with the tracking window details. 4.12. ✅ Validate Insurance → Clicking Validate should open the Insurance Validation window. | C13: Yes | D13: Thara | G13: Thara
